Failure # 1 (occurred at 2024-01-22_14-16-01)
[36mray::ResourceTrainable.train()[39m (pid=45486, ip=10.99.101.133, actor_id=4dbca2c0c3ec3ccfb651ef6701000000, repr=<ray.tune.trainable.util.mh_sim_trainable object at 0x2b1658fa8990>)
           ^^^^^^^^^^^^^^^^^^^^^^^^^^^^^^^^^^^^
           ^^^^^^^^^^^^^^^^^^^^^^^^^^^^^^^
  File "/home/adeyemi.n/.conda/envs/bed_allocation_proj/lib/python3.11/site-packages/ray/tune/trainable/trainable.py", line 342, in train
    raise skipped from exception_cause(skipped)
  File "/home/adeyemi.n/.conda/envs/bed_allocation_proj/lib/python3.11/site-packages/ray/tune/trainable/trainable.py", line 339, in train
    result = self.step()
             ^^^^^^^^^^^
           ^^^^^^^^^^^^^^^^^^^^^^^^^^^^^^^
  File "/home/adeyemi.n/MH_Simulation/Inpatient_Bed_Allocation_Optimization/experiments/parameter_tuning/__main__.py", line 25, in step
    self.optim_job.execute_iteration()
  File "/tmp/ray/session_2024-01-22_14-12-52_398640_30565/runtime_resources/working_dir_files/_ray_pkg_d932cc1b68e7afaa/optimizers/DD_PUSA/DD_PUSA.py", line 288, in execute_iteration
    if self.mocba & self.current_iteration % 5 == 0:
       ^^^^^^^^^^
AttributeError: 'dd_pusa' object has no attribute 'mocba'
