Failure # 1 (occurred at 2024-01-22_14-32-00)
[36mray::ResourceTrainable.train()[39m (pid=81035, ip=10.99.101.133, actor_id=9dbf80aa89db37b47b7121b001000000, repr=<ray.tune.trainable.util.mh_sim_trainable object at 0x2b126eaea710>)
           ^^^^^^^^^^^^^^^^^^^^^^^^^^^^^^^^^^^^
           ^^^^^^^^^^^^^^^^^^^^^^^^^^^^^^^
  File "/home/adeyemi.n/.conda/envs/bed_allocation_proj/lib/python3.11/site-packages/ray/tune/trainable/trainable.py", line 342, in train
    raise skipped from exception_cause(skipped)
  File "/home/adeyemi.n/.conda/envs/bed_allocation_proj/lib/python3.11/site-packages/ray/tune/trainable/trainable.py", line 339, in train
    result = self.step()
             ^^^^^^^^^^^
           ^^^^^^^^^^^^^^^^^^^^^^^^^^^^^^^
  File "/home/adeyemi.n/MH_Simulation/Inpatient_Bed_Allocation_Optimization/experiments/parameter_tuning/__main__.py", line 25, in step
    self.optim_job.execute_iteration()
  File "/tmp/ray/session_2024-01-22_14-29-56_427465_68576/runtime_resources/working_dir_files/_ray_pkg_c6c77474caf69996/optimizers/DD_PUSA/DD_PUSA.py", line 301, in execute_iteration
    if old_pset_ids is not None and self.get_attribute("id") != old_pset_ids:
                                    ^^^^^^^^^^^^^^^^^^
AttributeError: 'dd_pusa' object has no attribute 'get_attribute'
